Workbook

Sheet Supplier Invoice Statement
A1: Document No | B1: Payment No. | C1: Paid | D1: Invoiced | E1: Inv/cr | F1: Paid Amount | G1: Customer PO | H1: ABN | I1: Acct | J1: Check | K1: Payment No | L1: Bank Details | M1: Inv Month | N1: PO Number | O1: Location | P1: Type | Q1: $ Amount
A2: 24673 | B2: 1 | C2: Apr 17 | D2: Mar 23 | E2: INV_x000c_ | F2: S 742.50 | G2: PO-Sydney-223809 | H2: 1641 | I2: 7654320 | J2: 72 | K2: =CONCATENATE(A2,"_",B2) -> 24673_1 | L2: =H2&I2&J2 -> 1641765432072 | M2: =LEFT(D2,3) -> Mar | N2: =RIGHT(G2,6) -> 223809 | O2: =MID(G2,4,FIND("-",G2,4)-4) -> Sydney | P2: =UPPER(TRIM(CLEAN(E2))) -> INV | Q2: =SUBSTITUTE(SUBSTITUTE(F2,"S",""),MID(F2,2,1),"") -> 742.50 | R2: =TRIM(CLEAN(E2)) -> INV
A3: 24673 | B3: 1 | C3: Apr 20 | D3: Apr 01 | E3: inv_x000c_ | F3: S 1021.02 | G3: PO-Melbourne-327600 | H3: 2554 | I3: 4551221 | J3: 33 | K3: =CONCATENATE(A3,"_",B3) -> 24673_1 | L3: =H3&I3&J3 -> 2554455122133 | M3: =LEFT(D3,3) -> Apr | N3: =RIGHT(G3,6) -> 327600 | O3: =MID(G3,4,FIND("-",G3,4)-4) -> Melbourne | P3: =UPPER(TRIM(CLEAN(E3))) -> INV | Q3: =SUBSTITUTE(SUBSTITUTE(F3,"S",""),MID(F3,2,1),"") -> 1021.02 | R3: =TRIM(CLEAN(E3)) -> inv
A4: 24675 | B4: 1 | C4: Apr 05 | D4: Mar 16 | E4: INV_x000c_ | F4: S 409.53 | G4: PO-Melbourne-332589 | H4: 2554 | I4: 4551221 | J4: 33 | K4: =CONCATENATE(A4,"_",B4) -> 24675_1 | L4: =H4&I4&J4 -> 2554455122133 | M4: =LEFT(D4,3) -> Mar | N4: =RIGHT(G4,6) -> 332589 | O4: =MID(G4,4,FIND("-",G4,4)-4) -> Melbourne | P4: =UPPER(TRIM(CLEAN(E4))) -> INV | Q4: =SUBSTITUTE(SUBSTITUTE(F4,"S",""),MID(F4,2,1),"") -> 409.53 | R4: =TRIM(CLEAN(E4)) -> INV
A5: 24676 | B5: 1 | C5: Apr 20 | D5: Mar 25 | E5: cr _x000c_ | F5: S 234.96 | G5: PO-Melbourne-337131 | H5: 2554 | I5: 4551221 | J5: 33 | K5: =CONCATENATE(A5,"_",B5) -> 24676_1 | L5: =H5&I5&J5 -> 2554455122133 | M5: =LEFT(D5,3) -> Mar | N5: =RIGHT(G5,6) -> 337131 | O5: =MID(G5,4,FIND("-",G5,4)-4) -> Melbourne | P5: =UPPER(TRIM(CLEAN(E5))) -> CR | Q5: =SUBSTITUTE(SUBSTITUTE(F5,"S",""),MID(F5,2,1),"") -> 234.96 | R5: =TRIM(CLEAN(E5)) -> cr
A6: 24677 | B6: 1 | C6: Apr 10 | D6: Mar 17 | E6: cr_x000c_ | F6: S 450.12 | G6: PO-Melbourne-319376 | H6: 2554 | I6: 4551221 | J6: 33 | K6: =CONCATENATE(A6,"_",B6) -> 24677_1 | L6: =H6&I6&J6 -> 2554455122133 | M6: =LEFT(D6,3) -> Mar | N6: =RIGHT(G6,6) -> 319376 | O6: =MID(G6,4,FIND("-",G6,4)-4) -> Melbourne | P6: =UPPER(TRIM(CLEAN(E6))) -> CR | Q6: =SUBSTITUTE(SUBSTITUTE(F6,"S",""),MID(F6,2,1),"") -> 450.12 | R6: =TRIM(CLEAN(E6)) -> cr
A7: 24679 | B7: 1 | C7: Apr 30 | D7: Apr 09 | E7: inv_x000c_ | F7: S 114.18 | G7: PO-Melbourne-334724 | H7: 2554 | I7: 4551221 | J7: 33 | K7: =CONCATENATE(A7,"_",B7) -> 24679_1 | L7: =H7&I7&J7 -> 2554455122133 | M7: =LEFT(D7,3) -> Apr | N7: =RIGHT(G7,6) -> 334724 | O7: =MID(G7,4,FIND("-",G7,4)-4) -> Melbourne | P7: =UPPER(TRIM(CLEAN(E7))) -> INV | Q7: =SUBSTITUTE(SUBSTITUTE(F7,"S",""),MID(F7,2,1),"") -> 114.18 | R7: =TRIM(CLEAN(E7)) -> inv
A8: 24679 | B8: 2 | C8: Apr 30 | D8: Mar 23 | E8: inv _x000c_ | F8: S 930.93 | G8: PO-Melbourne-310607 | H8: 2554 | I8: 4551221 | J8: 33 | K8: =CONCATENATE(A8,"_",B8) -> 24679_2 | L8: =H8&I8&J8 -> 2554455122133 | M8: =LEFT(D8,3) -> Mar | N8: =RIGHT(G8,6) -> 310607 | O8: =MID(G8,4,FIND("-",G8,4)-4) -> Melbourne | P8: =UPPER(TRIM(CLEAN(E8))) -> INV | Q8: =SUBSTITUTE(SUBSTITUTE(F8,"S",""),MID(F8,2,1),"") -> 930.93 | R8: =TRIM(CLEAN(E8)) -> inv
A9: 24680 | B9: 1 | C9: Apr 14 | D9: Mar 27 | E9: inv_x000c_ | F9: S 466.29 | G9: PO-Sydney-226225 | H9: 1641 | I9: 7654320 | J9: 72 | K9: =CONCATENATE(A9,"_",B9) -> 24680_1 | L9: =H9&I9&J9 -> 1641765432072 | M9: =LEFT(D9,3) -> Mar | N9: =RIGHT(G9,6) -> 226225 | O9: =MID(G9,4,FIND("-",G9,4)-4) -> Sydney | P9: =UPPER(TRIM(CLEAN(E9))) -> INV | Q9: =SUBSTITUTE(SUBSTITUTE(F9,"S",""),MID(F9,2,1),"") -> 466.29 | R9: =TRIM(CLEAN(E9)) -> inv
A10: 24683 | B10: 1 | C10: Apr 27 | D10: Mar 22 | E10: inv_x000c_ | F10: S 222.42 | G10: PO-Sydney-223858 | H10: 1641 | I10: 7654320 | J10: 72 | K10: =CONCATENATE(A10,"_",B10) -> 24683_1 | L10: =H10&I10&J10 -> 1641765432072 | M10: =LEFT(D10,3) -> Mar | N10: =RIGHT(G10,6) -> 223858 | O10: =MID(G10,4,FIND("-",G10,4)-4) -> Sydney | P10: =UPPER(TRIM(CLEAN(E10))) -> INV | Q10: =SUBSTITUTE(SUBSTITUTE(F10,"S",""),MID(F10,2,1),"") -> 222.42 | R10: =TRIM(CLEAN(E10)) -> inv
A11: 24685 | B11: 1 | C11: Apr 11 | D11: Mar 09 | E11: INV_x000c_ | F11: S 679.80 | G11: PO-Sydney-211781 | H11: 1641 | I11: 7654320 | J11: 72 | K11: =CONCATENATE(A11,"_",B11) -> 24685_1 | L11: =H11&I11&J11 -> 1641765432072 | M11: =LEFT(D11,3) -> Mar | N11: =RIGHT(G11,6) -> 211781 | O11: =MID(G11,4,FIND("-",G11,4)-4) -> Sydney | P11: =UPPER(TRIM(CLEAN(E11))) -> INV | Q11: =SUBSTITUTE(SUBSTITUTE(F11,"S",""),MID(F11,2,1),"") -> 679.80 | R11: =TRIM(CLEAN(E11)) -> INV
A12: 24690 | B12: 1 | C12: Apr 23 | D12: Apr 04 | E12: inv_x000c_ | F12: S 171.93 | G12: PO-Sydney-232805 | H12: 1641 | I12: 7654320 | J12: 72 | K12: =CONCATENATE(A12,"_",B12) -> 24690_1 | L12: =H12&I12&J12 -> 1641765432072 | M12: =LEFT(D12,3) -> Apr | N12: =RIGHT(G12,6) -> 232805 | O12: =MID(G12,4,FIND("-",G12,4)-4) -> Sydney | P12: =UPPER(TRIM(CLEAN(E12))) -> INV | Q12: =SUBSTITUTE(SUBSTITUTE(F12,"S",""),MID(F12,2,1),"") -> 171.93 | R12: =TRIM(CLEAN(E12)) -> inv
A13: 24693 | B13: 1 | C13: Apr 06 | D13: Feb 24 | E13: Inv_x000c_ | F13: S 623.70 | G13: PO-Melbourne-312187 | H13: 2554 | I13: 4551221 | J13: 33 | K13: =CONCATENATE(A13,"_",B13) -> 24693_1 | L13: =H13&I13&J13 -> 2554455122133 | M13: =LEFT(D13,3) -> Feb | N13: =RIGHT(G13,6) -> 312187 | O13: =MID(G13,4,FIND("-",G13,4)-4) -> Melbourne | P13: =UPPER(TRIM(CLEAN(E13))) -> INV | Q13: =SUBSTITUTE(SUBSTITUTE(F13,"S",""),MID(F13,2,1),"") -> 623.70 | R13: =TRIM(CLEAN(E13)) -> Inv
... A85: 24902 | B85: 1 | C85: Apr 12 | D85: Mar 25 | E85: inv_x000c_ | F85: S 533.28 | G85: PO-Sydney-213342 | H85: 1641 | I85: 7654320 | J85: 72 | K85: =CONCATENATE(A85,"_",B85) -> 24902_1 | L85: =H85&I85&J85 -> 1641765432072 | M85: =LEFT(D85,3) -> Mar | N85: =RIGHT(G85,6) -> 213342 | O85: =MID(G85,4,FIND("-",G85,4)-4) -> Sydney | P85: =UPPER(TRIM(CLEAN(E85))) -> INV | Q85: =SUBSTITUTE(SUBSTITUTE(F85,"S",""),MID(F85,2,1),"") -> 533.28 | R85: =TRIM(CLEAN(E85)) -> inv

Sheet MC Invoice Report
A1: System Report for MedsCo April 2020
F2: Payments Made: | I2: Location: | L2: Penalty Rate: | M2: 0.0036
A4: Payment Ref | B4: Supplier Code | C4: Payment No. | D4: Invoice Date | E4: Due Date | F4: Payment Date | G4: Bank Details | H4: PO Number | I4: Location | J4: Amount | K4: Invoice Month | L4: Over Due By | M4: Late Charge
A5: 24673_1 | B5: MC2741 | C5: =545671 -> 545671 | D5: 40264 | E5: =WORKDAY(EDATE(D5,1)-1,1) -> 40295 | F5: 40269 | G5: 1641-7654320-72 | H5: 223809 | I5: Sydney | J5: 742.5 | K5: =TEXT(D5,"mmm") -> Mar | L5: =MAX(0,F5-E5) -> 0 | M5: =IF(J5>0,J5*$M$2*L5,0) -> 0
A6: 24673_1 | B6: MC2741 | C6: 545672 | D6: 40240 | E6: =WORKDAY(EDATE(D6,1)-1,1) -> 40273 | F6: 40270 | G6: 2554-4551221-33 | H6: 327600 | I6: Melbourne | J6: 1021.02 | K6: =TEXT(D6,"mmm") -> Mar | L6: =MAX(0,F6-E6) -> 0 | M6: =IF(J6>0,J6*$M$2*L6,0) -> 0
A7: 24675_1 | B7: MC2741 | C7: 545674 | D7: 40228 | E7: =WORKDAY(EDATE(D7,1)-1,1) -> 40256 | F7: 40271 | G7: 2554-4551221-33 | H7: 332589 | I7: Melbourne | J7: 409.53 | K7: =TEXT(D7,"mmm") -> Feb | L7: =MAX(0,F7-E7) -> 15 | M7: =IF(J7>0,J7*$M$2*L7,0) -> 22.11462
A8: 24676_1 | B8: MC2741 | C8: 545676 | D8: 40248 | E8: =WORKDAY(EDATE(D8,1)-1,1) -> 40280 | F8: 40271 | G8: 2554-4551221-33 | H8: 337131 | I8: Melbourne | J8: -234.96 | K8: =TEXT(D8,"mmm") -> Mar | L8: =MAX(0,F8-E8) -> 0 | M8: =IF(J8>0,J8*$M$2*L8,0) -> 0
A9: 24677_1 | B9: MC2741 | C9: 545677 | D9: 40258 | E9: =WORKDAY(EDATE(D9,1)-1,1) -> 40289 | F9: 40272 | G9: 2554-4551221-33 | H9: 319376 | I9: Melbourne | J9: -450.12 | K9: =TEXT(D9,"mmm") -> Mar | L9: =MAX(0,F9-E9) -> 0 | M9: =IF(J9>0,J9*$M$2*L9,0) -> 0
A10: 24679_1 | B10: MC2741 | C10: 545678 | D10: 40242 | E10: =WORKDAY(EDATE(D10,1)-1,1) -> 40273 | F10: 40272 | G10: 2554-4551221-33 | H10: 334724 | I10: Melbourne | J10: 114.18 | K10: =TEXT(D10,"mmm") -> Mar | L10: =MAX(0,F10-E10) -> 0 | M10: =IF(J10>0,J10*$M$2*L10,0) -> 0
A11: 24679_2 | B11: MC2741 | C11: 545679 | D11: 40243 | E11: =WORKDAY(EDATE(D11,1)-1,1) -> 40274 | F11: 40272 | G11: 2554-4551221-33 | H11: 310607 | I11: Melbourne | J11: 930.93 | K11: =TEXT(D11,"mmm") -> Mar | L11: =MAX(0,F11-E11) -> 0 | M11: =IF(J11>0,J11*$M$2*L11,0) -> 0
A12: 24680_1 | B12: MC2741 | C12: 545681 | D12: 40266 | E12: =WORKDAY(EDATE(D12,1)-1,1) -> 40297 | F12: 40272 | G12: 1641-7654320-72 | H12: 226225 | I12: Sydney | J12: 466.29 | K12: =TEXT(D12,"mmm") -> Mar | L12: =MAX(0,F12-E12) -> 0 | M12: =IF(J12>0,J12*$M$2*L12,0) -> 0
A13: 24683_1 | B13: MC2741 | C13: 545682 | D13: 40253 | E13: =WORKDAY(EDATE(D13,1)-1,1) -> 40284 | F13: 40273 | G13: 1641-7654320-72 | H13: 223858 | I13: Sydney | J13: 222.42 | K13: =TEXT(D13,"mmm") -> Mar | L13: =MAX(0,F13-E13) -> 0 | M13: =IF(J13>0,J13*$M$2*L13,0) -> 0
A14: 24685_1 | B14: MC2741 | C14: 545683 | D14: 40251 | E14: =WORKDAY(EDATE(D14,1)-1,1) -> 40282 | F14: 40273 | G14: 1641-7654320-72 | H14: 211781 | I14: Sydney | J14: 679.8 | K14: =TEXT(D14,"mmm") -> Mar | L14: =MAX(0,F14-E14) -> 0 | M14: =IF(J14>0,J14*$M$2*L14,0) -> 0
A15: 24690_1 | B15: MC2741 | C15: 545685 | D15: 40255 | E15: =WORKDAY(EDATE(D15,1)-1,1) -> 40287 | F15: 40273 | G15: 1641-7654320-72 | H15: 232805 | I15: Sydney | J15: 171.93 | K15: =TEXT(D15,"mmm") -> Mar | L15: =MAX(0,F15-E15) -> 0 | M15: =IF(J15>0,J15*$M$2*L15,0) -> 0
A16: 24693_1 | B16: MC2741 | C16: 545687 | D16: 40229 | E16: =WORKDAY(EDATE(D16,1)-1,1) -> 40259 | F16: 40273 | G16: 2554-4551221-33 | H16: 312187 | I16: Melbourne | J16: 623.7 | K16: =TEXT(D16,"mmm") -> Feb | L16: =MAX(0,F16-E16) -> 14 | M16: =IF(J16>0,J16*$M$2*L16,0) -> 31.43448
A17: 24697_1 | B17: MC2741 | C17: 545689 | D17: 40244 | E17: =WORKDAY(EDATE(D17,1)-1,1) -> 40275 | F17: 40273 | G17: 2554-4551221-33 | H17: 319790 | I17: Melbourne | J17: 221.1 | K17: =TEXT(D17,"mmm") -> Mar | L17: =MAX(0,F17-E17) -> 0 | M17: =IF(J17>0,J17*$M$2*L17,0) -> 0
... A88: 24902_1 | B88: MC2741 | C88: 545790 | D88: 40259 | E88: =WORKDAY(EDATE(D88,1)-1,1) -> 40290 | F88: 40298 | G88: 1641-7654320-72 | H88: 213342 | I88: Sydney | J88: 533.28 | K88: =TEXT(D88,"mmm") -> Mar | L88: =MAX(0,F88-E88) -> 8 | M88: =IF(J88>0,J88*$M$2*L88,0) -> 15.358464

Sheet Recon Analysis
A1: Analysis for MedsCo April 2020
A3: Supplier Statement Total: | B3: =SUMPRODUCT(('Supplier Invoice Statement'!P2:P85="INV")*VALUE('Supplier Invoice Statement'!Q2:Q85))-SUMPRODUCT(('Supplier Invoice Statement'!P2:P85="CR")*VALUE('Supplier Invoice Statement'!Q2:Q85)) -> 45711.93
A4: DC Report Total Paid: | B4: =SUM('MC Invoice Report'!J5:J88) -> 45711.93
A5: Difference: | B5: =B3-B4 -> 0
A7: Region | B7: Number of Invoices | C7: Late Payments | D7: Total Paid
A8: Sydney | B8: =COUNTIF('MC Invoice Report'!I5:I88,A8) -> 40 | C8: =COUNTIFS('MC Invoice Report'!I5:I88,A8,'MC Invoice Report'!L5:L88,">0") -> 14 | D8: =SUMIF('MC Invoice Report'!I5:I88,A8,'MC Invoice Report'!J5:J88) -> 24082.74
A9: Melbourne | B9: =COUNTIF('MC Invoice Report'!I5:I88,A9) -> 44 | C9: =COUNTIFS('MC Invoice Report'!I5:I88,A9,'MC Invoice Report'!L5:L88,">0") -> 16 | D9: =SUMIF('MC Invoice Report'!I5:I88,A9,'MC Invoice Report'!J5:J88) -> 21629.19
A10: Total | B10: =SUM(B8:B9) -> 84 | C10: =SUM(C8:C9) -> 30 | D10: =SUM(D8:D9) -> 45711.93
A12: Checks and findings
A13: Credit notes on statement (count) | B13: =COUNTIF('Supplier Invoice Statement'!P2:P85,"CR") -> 3
A14: Credit notes total (shown positive on statement) | B14: =SUMPRODUCT(('Supplier Invoice Statement'!P2:P85="CR")*VALUE('Supplier Invoice Statement'!Q2:Q85)) -> 1285.35
A15: Statement total if credits were added, not subtracted | B15: =B3+2*B14 -> 48282.63
A16: Overstatement from ignoring credit sign | B16: =B15-B4 -> 2570.7
A17: Duplicate payment keys on statement | B17: =SUMPRODUCT(--(COUNTIF('Supplier Invoice Statement'!K2:K85,'Supplier Invoice Statement'!K2:K85)>1)) -> 2
A18: Late payments (share of all payments) | B18: =C10/B10 -> 0.35714286
A19: Average days overdue (late payments only) | B19: =SUMIF('MC Invoice Report'!L5:L88,">0")/C10 -> 9
A20: Total late charges | B20: =SUM('MC Invoice Report'!M5:M88) -> 574.13783
A22: Assumptions: credits are subtracted (the system report stores them as negatives). Late charge = amount x penalty rate (MC Invoice Report M2) x days overdue, applied per day to positive amounts only. Overdue days = payment date minus due date. Duplicate keys = rows sharing the same Document No and Payment No.

Sheet ASCII Table
A1: ASCII Table | F1: ASCII printable characters | K1: ASCII printable characters | P1: Extended ASCII characters
A2: Dec | B2: Binary | C2: Character | D2: Description | F2: Dec | G2: Binary | H2: Character | I2: Description | K2: Dec | L2: Binary | M2: Character | N2: Description | P2: Dec | Q2: Binary | R2: Character | S2: Description
A3: 0 | B3: 0 | C3: NUL | D3: null | F3: 33 | G3: 100001 | H3: ! | I3: exclamation mark | K3: 65 | L3: 1000001 | M3: A | P3: 128 | Q3: 10000000 | R3: 
A4: 1 | B4: 1 | C4: SOH | D4: start of header | F4: 34 | G4: 100010 | H4: " | I4: double quote | K4: 66 | L4: 1000010 | M4: B | P4: 129 | Q4: 10000001 | R4: 
A5: 2 | B5: 10 | C5: STX | D5: start of text | F5: 35 | G5: 100011 | H5: # | I5: number | K5: 67 | L5: 1000011 | M5: C | P5: 130 | Q5: 10000010 | R5: 
A6: 3 | B6: 11 | C6: ETX | D6: end of text | F6: 36 | G6: 100100 | H6: $ | I6: dollar | K6: 68 | L6: 1000100 | M6: D | P6: 131 | Q6: 10000011 | R6: 
A7: 4 | B7: 100 | C7: EOT | D7: end of transmission | F7: 37 | G7: 100101 | H7: % | I7: percent | K7: 69 | L7: 1000101 | M7: E | P7: 132 | Q7: 10000100 | R7: 
A8: 5 | B8: 101 | C8: ENQ | D8: enquiry | F8: 38 | G8: 100110 | H8: & | I8: ampersand | K8: 70 | L8: 1000110 | M8: F | P8: 133 | Q8: 10000101
A9: 6 | B9: 110 | C9: ACK | D9: acknowledge | F9: 39 | G9: 100111 | H9: ' | I9: single quote | K9: 71 | L9: 1000111 | M9: G | P9: 134 | Q9: 10000110 | R9: 
A10: 7 | B10: 111 | C10: BEL | D10: bell | F10: 40 | G10: 101000 | H10: ( | I10: left parenthesis | K10: 72 | L10: 1001000 | M10: H | P10: 135 | Q10: 10000111 | R10: 
A11: 8 | B11: 1000 | C11: BS | D11: backspace | F11: 41 | G11: 101001 | H11: ) | I11: right parenthesis | K11: 73 | L11: 1001001 | M11: I | P11: 136 | Q11: 10001000 | R11: 
A12: 9 | B12: 1001 | C12: HT | D12: horizontal tab | F12: 42 | G12: 101010 | H12: * | I12: asterisk | K12: 74 | L12: 1001010 | M12: J | P12: 137 | Q12: 10001001 | R12: 
A13: 10 | B13: 1010 | C13: LF | D13: line feed | F13: 43 | G13: 101011 | H13: + | I13: plus | K13: 75 | L13: 1001011 | M13: K | P13: 138 | Q13: 10001010 | R13: 
A14: 11 | B14: 1011 | C14: VT | D14: vertical tab | F14: 44 | G14: 101100 | H14: , | I14: comma | K14: 76 | L14: 1001100 | M14: L | P14: 139 | Q14: 10001011 | R14: 
A15: 12 | B15: 1100 | C15: FF | D15: form feed | F15: 45 | G15: 101101 | H15: - | I15: minus | K15: 77 | L15: 1001101 | M15: M | P15: 140 | Q15: 10001100 | R15: 
A16: 13 | B16: 1101 | C16: CR | D16: enter / carriage return | F16: 46 | G16: 101110 | H16: . | I16: period | K16: 78 | L16: 1001110 | M16: N | P16: 141 | Q16: 10001101 | R16: 
A17: 14 | B17: 1110 | C17: SO | D17: shift out | F17: 47 | G17: 101111 | H17: / | I17: slash | K17: 79 | L17: 1001111 | M17: O | P17: 142 | Q17: 10001110 | R17: 
A18: 15 | B18: 1111 | C18: SI | D18: shift in | F18: 48 | G18: 110000 | H18: 0 | I18: zero | K18: 80 | L18: 1010000 | M18: P | P18: 143 | Q18: 10001111 | R18: 
A19: 16 | B19: 10000 | C19: DLE | D19: data link escape | F19: 49 | G19: 110001 | H19: 1 | I19: one | K19: 81 | L19: 1010001 | M19: Q | P19: 144 | Q19: 10010000 | R19: 
A20: 17 | B20: 10001 | C20: DC1 | D20: device control 1 | F20: 50 | G20: 110010 | H20: 2 | I20: two | K20: 82 | L20: 1010010 | M20: R | P20: 145 | Q20: 10010001 | R20: 
A21: 18 | B21: 10010 | C21: DC2 | D21: device control 2 | F21: 51 | G21: 110011 | H21: 3 | I21: three | K21: 83 | L21: 1010011 | M21: S | P21: 146 | Q21: 10010010 | R21: 
A22: 19 | B22: 10011 | C22: DC3 | D22: device control 3 | F22: 52 | G22: 110100 | H22: 4 | I22: four | K22: 84 | L22: 1010100 | M22: T | P22: 147 | Q22: 10010011 | R22: 
A23: 20 | B23: 10100 | C23: DC4 | D23: device control 4 | F23: 53 | G23: 110101 | H23: 5 | I23: five | K23: 85 | L23: 1010101 | M23: U | P23: 148 | Q23: 10010100 | R23: 
A24: 21 | B24: 10101 | C24: NAK | D24: negative acknowledge | F24: 54 | G24: 110110 | H24: 6 | I24: six | K24: 86 | L24: 1010110 | M24: V | P24: 149 | Q24: 10010101 | R24: 
A25: 22 | B25: 10110 | C25: SYN | D25: synchronize | F25: 55 | G25: 110111 | H25: 7 | I25: seven | K25: 87 | L25: 1010111 | M25: W | P25: 150 | Q25: 10010110 | R25: 
A26: 23 | B26: 10111 | C26: ETB | D26: end of trans. block | F26: 56 | G26: 111000 | H26: 8 | I26: eight | K26: 88 | L26: 1011000 | M26: X | P26: 151 | Q26: 10010111 | R26: 
A27: 24 | B27: 11000 | C27: CAN | D27: cancel | F27: 57 | G27: 111001 | H27: 9 | I27: nine | K27: 89 | L27: 1011001 | M27: Y | P27: 152 | Q27: 10011000 | R27: 
A28: 25 | B28: 11001 | C28: EM | D28: end of medium | F28: 58 | G28: 111010 | H28: : | I28: colon | K28: 90 | L28: 1011010 | M28: Z | P28: 153 | Q28: 10011001 | R28: 
A29: 26 | B29: 11010 | C29: SUB | D29: substitute | F29: 59 | G29: 111011 | H29: ; | I29: semicolon | K29: 91 | L29: 1011011 | M29: [ | N29: left square bracket | P29: 154 | Q29: 10011010 | R29: 
A30: 27 | B30: 11011 | C30: ESC | D30: escape | F30: 60 | G30: 111100 | H30: < | I30: less than | K30: 92 | L30: 1011100 | M30: \ | N30: backslash | P30: 155 | Q30: 10011011 | R30: 
A31: 28 | B31: 11100 | C31: FS | D31: file separator | F31: 61 | G31: 111101 | H31: = | I31: equality sign | K31: 93 | L31: 1011101 | M31: ] | N31: right square bracket | P31: 156 | Q31: 10011100 | R31: 
A32: 29 | B32: 11101 | C32: GS | D32: group separator | F32: 62 | G32: 111110 | H32: > | I32: greater than | K32: 94 | L32: 1011110 | M32: ^ | N32: caret / circumflex | P32: 157 | Q32: 10011101 | R32: 
A33: 30 | B33: 11110 | C33: RS | D33: record separator | F33: 63 | G33: 111111 | H33: ? | I33: question mark | K33: 95 | L33: 1011111 | M33: _ | N33: underscore | P33: 158 | Q33: 10011110 | R33: 
A34: 31 | B34: 11111 | C34: US | D34: unit separator | F34: 64 | G34: 1000000 | H34: @ | I34: at sign | K34: 96 | L34: 1100000 | M34: ` | N34: grave / accent | P34: 159 | Q34: 10011111 | R34: 
A35: 32 | B35: 100000 | C35: Space | D35: space | K35: 97 | L35: 1100001 | M35: a | P35: 160 | Q35: 10100000 | S35: non breaking space
K36: 98 | L36: 1100010 | M36: b | P36: 161 | Q36: 10100001 | R36: ¡
K37: 99 | L37: 1100011 | M37: c | P37: 162 | Q37: 10100010 | R37: ¢ | S37: cent
K38: 100 | L38: 1100100 | M38: d | P38: 163 | Q38: 10100011 | R38: £ | S38: pound
K39: 101 | L39: 1100101 | M39: e | P39: 164 | Q39: 10100100 | R39: ¤ | S39: currency sign
K40: 102 | L40: 1100110 | M40: f | P40: 165 | Q40: 10100101 | R40: ¥ | S40: yen, yuan
...
